{
 "cells": [
  {
   "cell_type": "code",
   "execution_count": 1,
   "id": "6af69b89",
   "metadata": {
    "scrolled": true
   },
   "outputs": [],
   "source": [
    "#pip install app-store-scraper"
   ]
  },
  {
   "cell_type": "code",
   "execution_count": 6,
   "id": "f77730af",
   "metadata": {
    "scrolled": true
   },
   "outputs": [
    {
     "name": "stderr",
     "output_type": "stream",
     "text": [
      "2023-02-24 22:57:13,677 [ERROR] asyncio - Exception in callback BaseSelectorEventLoop._read_from_self()\n",
      "handle: <Handle BaseSelectorEventLoop._read_from_self()>\n",
      "Traceback (most recent call last):\n",
      "  File \"C:\\ProgramData\\Anaconda3\\lib\\asyncio\\events.py\", line 80, in _run\n",
      "    self._context.run(self._callback, *self._args)\n",
      "  File \"C:\\ProgramData\\Anaconda3\\lib\\asyncio\\selector_events.py\", line 115, in _read_from_self\n",
      "    data = self._ssock.recv(4096)\n",
      "ConnectionResetError: [WinError 10054] Foi forçado o cancelamento de uma conexão existente pelo host remoto\n",
      "2023-02-24 22:57:13,691 [ERROR] asyncio - Exception in callback BaseSelectorEventLoop._read_from_self()\n",
      "handle: <Handle BaseSelectorEventLoop._read_from_self()>\n",
      "Traceback (most recent call last):\n",
      "  File \"C:\\ProgramData\\Anaconda3\\lib\\asyncio\\events.py\", line 80, in _run\n",
      "    self._context.run(self._callback, *self._args)\n",
      "  File \"C:\\ProgramData\\Anaconda3\\lib\\asyncio\\selector_events.py\", line 115, in _read_from_self\n",
      "    data = self._ssock.recv(4096)\n",
      "ConnectionResetError: [WinError 10054] Foi forçado o cancelamento de uma conexão existente pelo host remoto\n",
      "2023-02-24 22:57:13,699 [ERROR] asyncio - Exception in callback BaseSelectorEventLoop._read_from_self()\n",
      "handle: <Handle BaseSelectorEventLoop._read_from_self()>\n",
      "Traceback (most recent call last):\n",
      "  File \"C:\\ProgramData\\Anaconda3\\lib\\asyncio\\events.py\", line 80, in _run\n",
      "    self._context.run(self._callback, *self._args)\n",
      "  File \"C:\\ProgramData\\Anaconda3\\lib\\asyncio\\selector_events.py\", line 115, in _read_from_self\n",
      "    data = self._ssock.recv(4096)\n",
      "ConnectionResetError: [WinError 10054] Foi forçado o cancelamento de uma conexão existente pelo host remoto\n",
      "2023-02-24 22:57:13,700 [ERROR] asyncio - Exception in callback BaseSelectorEventLoop._read_from_self()\n",
      "handle: <Handle BaseSelectorEventLoop._read_from_self()>\n",
      "Traceback (most recent call last):\n",
      "  File \"C:\\ProgramData\\Anaconda3\\lib\\asyncio\\events.py\", line 80, in _run\n",
      "    self._context.run(self._callback, *self._args)\n",
      "  File \"C:\\ProgramData\\Anaconda3\\lib\\asyncio\\selector_events.py\", line 115, in _read_from_self\n",
      "    data = self._ssock.recv(4096)\n",
      "ConnectionResetError: [WinError 10054] Foi forçado o cancelamento de uma conexão existente pelo host remoto\n",
      "2023-02-24 22:57:13,701 [ERROR] asyncio - Exception in callback BaseSelectorEventLoop._read_from_self()\n",
      "handle: <Handle BaseSelectorEventLoop._read_from_self()>\n",
      "Traceback (most recent call last):\n",
      "  File \"C:\\ProgramData\\Anaconda3\\lib\\asyncio\\events.py\", line 80, in _run\n",
      "    self._context.run(self._callback, *self._args)\n",
      "  File \"C:\\ProgramData\\Anaconda3\\lib\\asyncio\\selector_events.py\", line 115, in _read_from_self\n",
      "    data = self._ssock.recv(4096)\n",
      "ConnectionResetError: [WinError 10054] Foi forçado o cancelamento de uma conexão existente pelo host remoto\n",
      "2023-02-24 22:57:23,706 [ERROR] asyncio - Exception in callback BaseSelectorEventLoop._read_from_self()\n",
      "handle: <Handle BaseSelectorEventLoop._read_from_self()>\n",
      "Traceback (most recent call last):\n",
      "  File \"C:\\ProgramData\\Anaconda3\\lib\\asyncio\\events.py\", line 80, in _run\n",
      "    self._context.run(self._callback, *self._args)\n",
      "  File \"C:\\ProgramData\\Anaconda3\\lib\\asyncio\\selector_events.py\", line 115, in _read_from_self\n",
      "    data = self._ssock.recv(4096)\n",
      "ConnectionResetError: [WinError 10054] Foi forçado o cancelamento de uma conexão existente pelo host remoto\n"
     ]
    }
   ],
   "source": [
    "import pandas as pd\n",
    "import numpy as np\n",
    "from app_store_scraper import AppStore\n",
    "\n",
    "class AppReviewsScraper:\n",
    "    \"\"\"\n",
    "    A class to scrape app reviews from the Apple App Store.\n",
    "\n",
    "    Parameters\n",
    "    ----------\n",
    "    country : str\n",
    "        Abbreviation in English of the country you want to scrape the reviews.\n",
    "    app_name : str\n",
    "        The name of the app.\n",
    "    app_id : int\n",
    "        The app id on the app store. To find this id, just google app_name on app store.\n",
    "        The end of the url says id followed by the id number.\n",
    "    how_many : int\n",
    "        The number of reviews you want to scrape from the app store.\n",
    "\n",
    "    Attributes\n",
    "    ----------\n",
    "    country : str\n",
    "        Abbreviation in English of the country you want to scrape the reviews.\n",
    "    app_name : str\n",
    "        The name of the app.\n",
    "    app_id : int\n",
    "        The app id on the app store.\n",
    "    how_many : int\n",
    "        The number of reviews you want to scrape from the app store.\n",
    "    app_store : AppStore\n",
    "        An instance of the AppStore class from the app_store_scraper package.\n",
    "\n",
    "    Methods\n",
    "    -------\n",
    "    scrape_reviews():\n",
    "        Scrapes reviews for the given app from the App Store.\n",
    "        Returns a Pandas DataFrame containing the reviews and their associated information.\n",
    "    \n",
    "    export_to_csv(file_path):\n",
    "        Exports the scraped reviews to a CSV file at the given file path.\n",
    "    \"\"\"\n",
    "    def __init__(self, country, app_name, app_id, how_many):\n",
    "        self.country = country\n",
    "        self.app_name = app_name\n",
    "        self.app_id = app_id\n",
    "        self.how_many = how_many\n",
    "        self.app_store = AppStore(country=self.country, app_name=self.app_name, app_id=self.app_id)\n",
    "        \n",
    "    def scrape_reviews(self):\n",
    "        self.app_store.review(how_many=self.how_many)\n",
    "        reviews_df = pd.DataFrame(np.array(self.app_store.reviews), columns=['review'])\n",
    "        reviews_df = reviews_df.join(pd.DataFrame(reviews_df.pop('review').tolist()))\n",
    "        return reviews_df\n",
    "    \n",
    "    def export_to_csv(self, file_path):\n",
    "        reviews_df = self.scrape_reviews()\n",
    "        reviews_df.to_csv(file_path, index=False)"
   ]
  },
  {
   "cell_type": "code",
   "execution_count": null,
   "id": "23a4ba66",
   "metadata": {
    "scrolled": true
   },
   "outputs": [
    {
     "name": "stderr",
     "output_type": "stream",
     "text": [
      "2023-02-24 23:00:23,971 [ERROR] asyncio - Exception in callback BaseSelectorEventLoop._read_from_self()\n",
      "handle: <Handle BaseSelectorEventLoop._read_from_self()>\n",
      "Traceback (most recent call last):\n",
      "  File \"C:\\ProgramData\\Anaconda3\\lib\\asyncio\\events.py\", line 80, in _run\n",
      "    self._context.run(self._callback, *self._args)\n",
      "  File \"C:\\ProgramData\\Anaconda3\\lib\\asyncio\\selector_events.py\", line 115, in _read_from_self\n",
      "    data = self._ssock.recv(4096)\n",
      "ConnectionResetError: [WinError 10054] Foi forçado o cancelamento de uma conexão existente pelo host remoto\n",
      "2023-02-24 23:00:23,973 [ERROR] asyncio - Exception in callback BaseSelectorEventLoop._read_from_self()\n",
      "handle: <Handle BaseSelectorEventLoop._read_from_self()>\n",
      "Traceback (most recent call last):\n",
      "  File \"C:\\ProgramData\\Anaconda3\\lib\\asyncio\\events.py\", line 80, in _run\n",
      "    self._context.run(self._callback, *self._args)\n",
      "  File \"C:\\ProgramData\\Anaconda3\\lib\\asyncio\\selector_events.py\", line 115, in _read_from_self\n",
      "    data = self._ssock.recv(4096)\n",
      "ConnectionResetError: [WinError 10054] Foi forçado o cancelamento de uma conexão existente pelo host remoto\n",
      "2023-02-24 23:00:23,973 [ERROR] asyncio - Exception in callback BaseSelectorEventLoop._read_from_self()\n",
      "handle: <Handle BaseSelectorEventLoop._read_from_self()>\n",
      "Traceback (most recent call last):\n",
      "  File \"C:\\ProgramData\\Anaconda3\\lib\\asyncio\\events.py\", line 80, in _run\n",
      "    self._context.run(self._callback, *self._args)\n",
      "  File \"C:\\ProgramData\\Anaconda3\\lib\\asyncio\\selector_events.py\", line 115, in _read_from_self\n",
      "    data = self._ssock.recv(4096)\n",
      "ConnectionResetError: [WinError 10054] Foi forçado o cancelamento de uma conexão existente pelo host remoto\n",
      "2023-02-24 23:00:35,289 [INFO] Base - Initialised: AppStore('us', 'scruff', 380015247)\n",
      "2023-02-24 23:00:43,988 [ERROR] asyncio - Exception in callback BaseSelectorEventLoop._read_from_self()\n",
      "handle: <Handle BaseSelectorEventLoop._read_from_self()>\n",
      "Traceback (most recent call last):\n",
      "  File \"C:\\ProgramData\\Anaconda3\\lib\\asyncio\\events.py\", line 80, in _run\n",
      "    self._context.run(self._callback, *self._args)\n",
      "  File \"C:\\ProgramData\\Anaconda3\\lib\\asyncio\\selector_events.py\", line 115, in _read_from_self\n",
      "    data = self._ssock.recv(4096)\n",
      "ConnectionResetError: [WinError 10054] Foi forçado o cancelamento de uma conexão existente pelo host remoto\n",
      "2023-02-24 23:00:43,988 [ERROR] asyncio - Exception in callback BaseSelectorEventLoop._read_from_self()\n",
      "handle: <Handle BaseSelectorEventLoop._read_from_self()>\n",
      "Traceback (most recent call last):\n",
      "  File \"C:\\ProgramData\\Anaconda3\\lib\\asyncio\\events.py\", line 80, in _run\n",
      "    self._context.run(self._callback, *self._args)\n",
      "  File \"C:\\ProgramData\\Anaconda3\\lib\\asyncio\\selector_events.py\", line 115, in _read_from_self\n",
      "    data = self._ssock.recv(4096)\n",
      "ConnectionResetError: [WinError 10054] Foi forçado o cancelamento de uma conexão existente pelo host remoto\n",
      "2023-02-24 23:00:53,994 [INFO] Base - Ready to fetch reviews from: https://apps.apple.com/us/app/scruff/id380015247\n",
      "2023-02-24 23:01:03,995 [ERROR] asyncio - Exception in callback BaseSelectorEventLoop._read_from_self()\n",
      "handle: <Handle BaseSelectorEventLoop._read_from_self()>\n",
      "Traceback (most recent call last):\n",
      "  File \"C:\\ProgramData\\Anaconda3\\lib\\asyncio\\events.py\", line 80, in _run\n",
      "    self._context.run(self._callback, *self._args)\n",
      "  File \"C:\\ProgramData\\Anaconda3\\lib\\asyncio\\selector_events.py\", line 115, in _read_from_self\n",
      "    data = self._ssock.recv(4096)\n",
      "ConnectionResetError: [WinError 10054] Foi forçado o cancelamento de uma conexão existente pelo host remoto\n",
      "2023-02-24 23:01:03,995 [ERROR] asyncio - Exception in callback BaseSelectorEventLoop._read_from_self()\n",
      "handle: <Handle BaseSelectorEventLoop._read_from_self()>\n",
      "Traceback (most recent call last):\n",
      "  File \"C:\\ProgramData\\Anaconda3\\lib\\asyncio\\events.py\", line 80, in _run\n",
      "    self._context.run(self._callback, *self._args)\n",
      "  File \"C:\\ProgramData\\Anaconda3\\lib\\asyncio\\selector_events.py\", line 115, in _read_from_self\n",
      "    data = self._ssock.recv(4096)\n",
      "ConnectionResetError: [WinError 10054] Foi forçado o cancelamento de uma conexão existente pelo host remoto\n",
      "2023-02-24 23:01:14,008 [ERROR] asyncio - Exception in callback BaseSelectorEventLoop._read_from_self()\n",
      "handle: <Handle BaseSelectorEventLoop._read_from_self()>\n",
      "Traceback (most recent call last):\n",
      "  File \"C:\\ProgramData\\Anaconda3\\lib\\asyncio\\events.py\", line 80, in _run\n",
      "    self._context.run(self._callback, *self._args)\n",
      "  File \"C:\\ProgramData\\Anaconda3\\lib\\asyncio\\selector_events.py\", line 115, in _read_from_self\n",
      "    data = self._ssock.recv(4096)\n",
      "ConnectionResetError: [WinError 10054] Foi forçado o cancelamento de uma conexão existente pelo host remoto\n",
      "2023-02-24 23:01:14,008 [ERROR] asyncio - Exception in callback BaseSelectorEventLoop._read_from_self()\n",
      "handle: <Handle BaseSelectorEventLoop._read_from_self()>\n",
      "Traceback (most recent call last):\n",
      "  File \"C:\\ProgramData\\Anaconda3\\lib\\asyncio\\events.py\", line 80, in _run\n",
      "    self._context.run(self._callback, *self._args)\n",
      "  File \"C:\\ProgramData\\Anaconda3\\lib\\asyncio\\selector_events.py\", line 115, in _read_from_self\n",
      "    data = self._ssock.recv(4096)\n",
      "ConnectionResetError: [WinError 10054] Foi forçado o cancelamento de uma conexão existente pelo host remoto\n",
      "2023-02-24 23:01:14,008 [ERROR] asyncio - Exception in callback BaseSelectorEventLoop._read_from_self()\n",
      "handle: <Handle BaseSelectorEventLoop._read_from_self()>\n",
      "Traceback (most recent call last):\n",
      "  File \"C:\\ProgramData\\Anaconda3\\lib\\asyncio\\events.py\", line 80, in _run\n",
      "    self._context.run(self._callback, *self._args)\n",
      "  File \"C:\\ProgramData\\Anaconda3\\lib\\asyncio\\selector_events.py\", line 115, in _read_from_self\n",
      "    data = self._ssock.recv(4096)\n",
      "ConnectionResetError: [WinError 10054] Foi forçado o cancelamento de uma conexão existente pelo host remoto\n",
      "2023-02-24 23:01:23,107 [INFO] Base - [id:380015247] Fetched 20 reviews (20 fetched in total)\n",
      "2023-02-24 23:01:24,018 [ERROR] asyncio - Exception in callback BaseSelectorEventLoop._read_from_self()\n",
      "handle: <Handle BaseSelectorEventLoop._read_from_self()>\n",
      "Traceback (most recent call last):\n",
      "  File \"C:\\ProgramData\\Anaconda3\\lib\\asyncio\\events.py\", line 80, in _run\n",
      "    self._context.run(self._callback, *self._args)\n",
      "  File \"C:\\ProgramData\\Anaconda3\\lib\\asyncio\\selector_events.py\", line 115, in _read_from_self\n",
      "    data = self._ssock.recv(4096)\n",
      "ConnectionResetError: [WinError 10054] Foi forçado o cancelamento de uma conexão existente pelo host remoto\n",
      "2023-02-24 23:01:24,021 [ERROR] asyncio - Exception in callback BaseSelectorEventLoop._read_from_self()\n",
      "handle: <Handle BaseSelectorEventLoop._read_from_self()>\n",
      "Traceback (most recent call last):\n",
      "  File \"C:\\ProgramData\\Anaconda3\\lib\\asyncio\\events.py\", line 80, in _run\n",
      "    self._context.run(self._callback, *self._args)\n",
      "  File \"C:\\ProgramData\\Anaconda3\\lib\\asyncio\\selector_events.py\", line 115, in _read_from_self\n",
      "    data = self._ssock.recv(4096)\n",
      "ConnectionResetError: [WinError 10054] Foi forçado o cancelamento de uma conexão existente pelo host remoto\n",
      "2023-02-24 23:01:34,027 [ERROR] asyncio - Exception in callback BaseSelectorEventLoop._read_from_self()\n",
      "handle: <Handle BaseSelectorEventLoop._read_from_self()>\n",
      "Traceback (most recent call last):\n",
      "  File \"C:\\ProgramData\\Anaconda3\\lib\\asyncio\\events.py\", line 80, in _run\n",
      "    self._context.run(self._callback, *self._args)\n",
      "  File \"C:\\ProgramData\\Anaconda3\\lib\\asyncio\\selector_events.py\", line 115, in _read_from_self\n",
      "    data = self._ssock.recv(4096)\n",
      "ConnectionResetError: [WinError 10054] Foi forçado o cancelamento de uma conexão existente pelo host remoto\n",
      "2023-02-24 23:01:34,027 [ERROR] asyncio - Exception in callback BaseSelectorEventLoop._read_from_self()\n",
      "handle: <Handle BaseSelectorEventLoop._read_from_self()>\n",
      "Traceback (most recent call last):\n",
      "  File \"C:\\ProgramData\\Anaconda3\\lib\\asyncio\\events.py\", line 80, in _run\n",
      "    self._context.run(self._callback, *self._args)\n",
      "  File \"C:\\ProgramData\\Anaconda3\\lib\\asyncio\\selector_events.py\", line 115, in _read_from_self\n",
      "    data = self._ssock.recv(4096)\n",
      "ConnectionResetError: [WinError 10054] Foi forçado o cancelamento de uma conexão existente pelo host remoto\n",
      "2023-02-24 23:01:44,032 [ERROR] asyncio - Exception in callback BaseSelectorEventLoop._read_from_self()\n",
      "handle: <Handle BaseSelectorEventLoop._read_from_self()>\n",
      "Traceback (most recent call last):\n",
      "  File \"C:\\ProgramData\\Anaconda3\\lib\\asyncio\\events.py\", line 80, in _run\n",
      "    self._context.run(self._callback, *self._args)\n",
      "  File \"C:\\ProgramData\\Anaconda3\\lib\\asyncio\\selector_events.py\", line 115, in _read_from_self\n",
      "    data = self._ssock.recv(4096)\n",
      "ConnectionResetError: [WinError 10054] Foi forçado o cancelamento de uma conexão existente pelo host remoto\n",
      "2023-02-24 23:01:44,034 [ERROR] asyncio - Exception in callback BaseSelectorEventLoop._read_from_self()\n",
      "handle: <Handle BaseSelectorEventLoop._read_from_self()>\n",
      "Traceback (most recent call last):\n",
      "  File \"C:\\ProgramData\\Anaconda3\\lib\\asyncio\\events.py\", line 80, in _run\n",
      "    self._context.run(self._callback, *self._args)\n",
      "  File \"C:\\ProgramData\\Anaconda3\\lib\\asyncio\\selector_events.py\", line 115, in _read_from_self\n",
      "    data = self._ssock.recv(4096)\n",
      "ConnectionResetError: [WinError 10054] Foi forçado o cancelamento de uma conexão existente pelo host remoto\n"
     ]
    },
    {
     "name": "stderr",
     "output_type": "stream",
     "text": [
      "2023-02-24 23:01:44,259 [INFO] Base - [id:380015247] Fetched 180 reviews (180 fetched in total)\n",
      "2023-02-24 23:01:54,038 [ERROR] asyncio - Exception in callback BaseSelectorEventLoop._read_from_self()\n",
      "handle: <Handle BaseSelectorEventLoop._read_from_self()>\n",
      "Traceback (most recent call last):\n",
      "  File \"C:\\ProgramData\\Anaconda3\\lib\\asyncio\\events.py\", line 80, in _run\n",
      "    self._context.run(self._callback, *self._args)\n",
      "  File \"C:\\ProgramData\\Anaconda3\\lib\\asyncio\\selector_events.py\", line 115, in _read_from_self\n",
      "    data = self._ssock.recv(4096)\n",
      "ConnectionResetError: [WinError 10054] Foi forçado o cancelamento de uma conexão existente pelo host remoto\n",
      "2023-02-24 23:01:54,038 [ERROR] asyncio - Exception in callback BaseSelectorEventLoop._read_from_self()\n",
      "handle: <Handle BaseSelectorEventLoop._read_from_self()>\n",
      "Traceback (most recent call last):\n",
      "  File \"C:\\ProgramData\\Anaconda3\\lib\\asyncio\\events.py\", line 80, in _run\n",
      "    self._context.run(self._callback, *self._args)\n",
      "  File \"C:\\ProgramData\\Anaconda3\\lib\\asyncio\\selector_events.py\", line 115, in _read_from_self\n",
      "    data = self._ssock.recv(4096)\n",
      "ConnectionResetError: [WinError 10054] Foi forçado o cancelamento de uma conexão existente pelo host remoto\n"
     ]
    }
   ],
   "source": [
    "# instantiate the class for Grindr app reviews\n",
    "grindr_scraper = AppReviewsScraper(country='us', app_name='grindr', app_id='319881193', how_many=2000)\n",
    "\n",
    "# scrape the reviews and export them to a CSV file\n",
    "grindr_scraper.export_to_csv('grindr_reviews.csv')\n",
    "\n",
    "# instantiate the class for Scruff app reviews\n",
    "scruff_scraper = AppReviewsScraper(country='us', app_name='scruff', app_id='380015247', how_many=2000)\n",
    "\n",
    "# scrape the reviews and export them to a CSV file\n",
    "scruff_scraper.export_to_csv('scruff_reviews.csv')\n",
    "\n",
    "# instantiate the class for Hornet app reviews\n",
    "hornet_scraper = AppReviewsScraper(country='us', app_name='hornet', app_id='462678375', how_many=2000)\n",
    "\n",
    "# scrape the reviews and export them to a CSV file\n",
    "hornet_scraper.export_to_csv('hornet_reviews.csv')"
   ]
  }
 ],
 "metadata": {
  "kernelspec": {
   "display_name": "Python 3",
   "language": "python",
   "name": "python3"
  },
  "language_info": {
   "codemirror_mode": {
    "name": "ipython",
    "version": 3
   },
   "file_extension": ".py",
   "mimetype": "text/x-python",
   "name": "python",
   "nbconvert_exporter": "python",
   "pygments_lexer": "ipython3",
   "version": "3.11.2"
  },
  "vscode": {
   "interpreter": {
    "hash": "ebe0b94344c0f4b7f5f23c6264dd64bfe6fbc608d3c775e4a8d0508d40af3b3e"
   }
  }
 },
 "nbformat": 4,
 "nbformat_minor": 5
}
